<mujoco model="humanoid">
  <option gravity='0 0 -9.81' solver='PGS' timestep="0.002"/>
  <option integrator="implicitfast" />
  <size njmax="500" nconmax="100" />
  <compiler angle="radian" meshdir="meshes/" eulerseq="zyx"/>
  <default>
    <joint type="hinge" limited="true" />
  </default>
  <asset>
    <texture type="skybox" builtin="gradient" rgb1="0.3 0.5 0.7" rgb2="0 0 0" width="512" height="512" />
    <texture name="texplane" type="2d" builtin="checker" rgb1=".2 .3 .4" rgb2=".1 0.15 0.2" width="512" height="512" mark="cross" markrgb=".8 .8 .8" />
    <material name="matplane" reflectance="0.3" texture="texplane" texrepeat="1 1" texuniform="true" />
    <mesh name="pelvis" content_type="model/stl" file="pelvis.STL"/>
    <mesh name="hip_roll_l_link" content_type="model/stl" file="hip_roll_l_link.STL"/>
    <mesh name="hip_pitch_l_link" content_type="model/stl" file="hip_pitch_l_link.STL"/>
    <mesh name="hip_yaw_l_link" content_type="model/stl" file="hip_yaw_l_link.STL"/>
    <mesh name="knee_pitch_l_link" content_type="model/stl" file="knee_pitch_l_link.STL"/>
    <mesh name="ankle_pitch_l_link" content_type="model/stl" file="ankle_pitch_l_link.STL"/>
    <mesh name="ankle_roll_l_link" content_type="model/stl" file="ankle_roll_l_link.STL"/>
    <mesh name="hip_roll_r_link" content_type="model/stl" file="hip_roll_r_link.STL"/>
    <mesh name="hip_pitch_r_link" content_type="model/stl" file="hip_pitch_r_link.STL"/>
    <mesh name="hip_yaw_r_link" content_type="model/stl" file="hip_yaw_r_link.STL"/>
    <mesh name="knee_pitch_r_link" content_type="model/stl" file="knee_pitch_r_link.STL"/>
    <mesh name="ankle_pitch_r_link" content_type="model/stl" file="ankle_pitch_r_link.STL"/>
    <mesh name="ankle_roll_r_link" content_type="model/stl" file="ankle_roll_r_link.STL"/>
    <mesh name="waist_yaw_link" content_type="model/stl" file="waist_yaw_link.STL"/>
    <mesh name="head_yaw_link" content_type="model/stl" file="head_yaw_link.STL"/>
    <mesh name="head_pitch_link" content_type="model/stl" file="head_pitch_link.STL"/>
    <mesh name="head_roll_link" content_type="model/stl" file="head_roll_link.STL"/>
    <mesh name="camera_head_link" content_type="model/stl" file="camera_head_link.STL"/>
    <mesh name="shoulder_pitch_l_link" content_type="model/stl" file="shoulder_pitch_l_link.STL"/>
    <mesh name="shoulder_roll_l_link" content_type="model/stl" file="shoulder_roll_l_link.STL"/>
    <mesh name="shoulder_yaw_l_link" content_type="model/stl" file="shoulder_yaw_l_link.STL"/>
    <mesh name="elbow_pitch_l_link" content_type="model/stl" file="elbow_pitch_l_link.STL"/>
    <mesh name="elbow_yaw_l_link" content_type="model/stl" file="elbow_yaw_l_link.STL"/>
    <mesh name="wrist_pitch_l_link" content_type="model/stl" file="wrist_pitch_l_link.STL"/>
    <mesh name="wrist_roll_l_link" content_type="model/stl" file="wrist_roll_l_link.STL"/>
    <mesh name="shoulder_pitch_r_link" content_type="model/stl" file="shoulder_pitch_r_link.STL"/>
    <mesh name="shoulder_roll_r_link" content_type="model/stl" file="shoulder_roll_r_link.STL"/>
    <mesh name="shoulder_yaw_r_link" content_type="model/stl" file="shoulder_yaw_r_link.STL"/>
    <mesh name="elbow_pitch_r_link" content_type="model/stl" file="elbow_pitch_r_link.STL"/>
    <mesh name="elbow_yaw_r_link" content_type="model/stl" file="elbow_yaw_r_link.STL"/>
    <mesh name="wrist_pitch_r_link" content_type="model/stl" file="wrist_pitch_r_link.STL"/>
    <mesh name="wrist_roll_r_link" content_type="model/stl" file="wrist_roll_r_link.STL"/>
    <mesh name="camera_body_front_link" content_type="model/stl" file="camera_body_front_link.STL"/>
    <mesh name="camera_body_back_link" content_type="model/stl" file="camera_body_back_link.STL"/>
    <mesh name="L_base_link" content_type="model/stl" file="L_base_link.STL"/>
    <mesh name="left_thumb_1" content_type="model/stl" file="left_thumb_1.STL"/>
    <mesh name="left_thumb_2" content_type="model/stl" file="left_thumb_2.STL"/>
    <mesh name="left_thumb_3" content_type="model/stl" file="left_thumb_3.STL"/>
    <mesh name="left_thumb_4" content_type="model/stl" file="left_thumb_4.STL"/>
    <mesh name="left_index_1" content_type="model/stl" file="left_index_1.STL"/>
    <mesh name="left_index_2" content_type="model/stl" file="left_index_2.STL"/>
    <mesh name="left_middle_1" content_type="model/stl" file="left_middle_1.STL"/>
    <mesh name="left_middle_2" content_type="model/stl" file="left_middle_2.STL"/>
    <mesh name="left_ring_1" content_type="model/stl" file="left_ring_1.STL"/>
    <mesh name="left_ring_2" content_type="model/stl" file="left_ring_2.STL"/>
    <mesh name="left_little_1" content_type="model/stl" file="left_little_1.STL"/>
    <mesh name="left_little_2" content_type="model/stl" file="left_little_2.STL"/>
    <mesh name="R_base_link" content_type="model/stl" file="R_base_link.STL"/>
    <mesh name="right_thumb_1" content_type="model/stl" file="right_thumb_1.STL"/>
    <mesh name="right_thumb_2" content_type="model/stl" file="right_thumb_2.STL"/>
    <mesh name="right_thumb_3" content_type="model/stl" file="right_thumb_3.STL"/>
    <mesh name="right_thumb_4" content_type="model/stl" file="right_thumb_4.STL"/>
    <mesh name="right_index_1" content_type="model/stl" file="right_index_1.STL"/>
    <mesh name="right_index_2" content_type="model/stl" file="right_index_2.STL"/>
    <mesh name="right_middle_1" content_type="model/stl" file="right_middle_1.STL"/>
    <mesh name="right_middle_2" content_type="model/stl" file="right_middle_2.STL"/>
    <mesh name="right_ring_1" content_type="model/stl" file="right_ring_1.STL"/>
    <mesh name="right_ring_2" content_type="model/stl" file="right_ring_2.STL"/>
    <mesh name="right_little_1" content_type="model/stl" file="right_little_1.STL"/>
    <mesh name="right_little_2" content_type="model/stl" file="right_little_2.STL"/>
  </asset>

  <worldbody>
    <light directional="true" diffuse=".4 .4 .4" specular="0.1 0.1 0.1" pos="0 0 5.0" dir="0 0 -1" castshadow="false" />
    <light directional="true" diffuse=".6 .6 .6" specular="0.2 0.2 0.2" pos="0 0 4" dir="0 0 -1" />
    <geom name="floor" pos="0 0 0" size="100 100 1" type="plane" material="matplane" margin="0.001" contype="1" conaffinity="15" friction="1 0.005 0.0001" />

    <body name="pelvis" pos="0 0 1.0">
      <freejoint name="root" />
      <inertial pos="0.001537 0.000283 0.177608" quat="0.997803 1.42418e-06 0.0154267 -0.0644277" mass="27.7717" diaginertia="0.952918 0.922015 0.196947"/>
      <geom type="mesh" contype="0" conaffinity="0" group="1" density="0" rgba="0.752941 0.752941 0.752941 1" mesh="pelvis"/>
      <geom size="0.085 0.055" pos="-0.02 0 -0.11" quat="0.707388 0.706825 0 0" type="cylinder" rgba="0.752941 0.752941 0.752941 1"/>
      <site name='imu' size='0.01' pos='0.0 0 0.0'/>
      <body name="hip_roll_l_link" pos="0 0.028 -0.0857">
        <inertial pos="-0.001848 0.055849 -0.036017" quat="0.242041 0.661501 0.270146 0.656394" mass="0.672983" diaginertia="0.0035288 0.00296741 0.00101678"/>
        <joint name="hip_roll_l_joint" pos="0 0 0" axis="1 0 0" range="-0.79 0.79" damping="10"/>
        <geom type="mesh" contype="0" conaffinity="0" group="1" density="0" rgba="0.752941 0.752941 0.752941 1" mesh="hip_roll_l_link"/>
        <body name="hip_pitch_l_link" pos="0 0.122 -0.046">
          <inertial pos="0.001081 -8.8e-05 -0.013133" quat="0.703908 -0.0464278 -0.0604083 0.706193" mass="3.95191" diaginertia="0.0155995 0.0108766 0.00930186"/>
          <joint name="hip_pitch_l_joint" pos="0 0 0" axis="0 1 0" range="-2.79 2.09" damping="10"/>
          <geom type="mesh" contype="0" conaffinity="0" group="1" density="0" rgba="0.752941 0.752941 0.752941 1" mesh="hip_pitch_l_link"/>
          <body name="hip_yaw_l_link" pos="0 -0.00015 -0.0987">
            <inertial pos="0.004102 -0.006542 -0.121068" quat="0.685682 -0.0129439 0.0149542 0.727633" mass="6.6708" diaginertia="0.0533758 0.0495596 0.0178685"/>
            <joint name="hip_yaw_l_joint" pos="0 0 0" axis="0 0 1" range="-1.04 1.04" damping="5"/>
            <geom type="mesh" contype="0" conaffinity="0" group="1" density="0" rgba="0.752941 0.752941 0.752941 1" mesh="hip_yaw_l_link"/>
            <geom size="0.03 0.1" pos="0 0 -0.1" type="cylinder" rgba="0.752941 0.752941 0.752941 1"/>
            <body name="knee_pitch_l_link" pos="0 0.00010715 -0.3013">
              <inertial pos="0.00018 0.001915 -0.178653" quat="0.741662 0.0200239 0.0403837 0.669257" mass="2.31269" diaginertia="0.0309319 0.0304477 0.00269639"/>
              <joint name="knee_pitch_l_joint" pos="0 0 0" axis="0 1 0" range="0 2.39" damping="10"/>
              <geom type="mesh" contype="0" conaffinity="0" group="1" density="0" rgba="0.752941 0.752941 0.752941 1" mesh="knee_pitch_l_link"/>
              <geom size="0.03 0.15" pos="0 0 -0.15" type="cylinder" rgba="0.752941 0.752941 0.752941 1"/>
              <body name="ankle_pitch_l_link" pos="0 0 -0.4">
                <inertial pos="0 0 0" quat="0.5 0.5 -0.5 0.5" mass="0.111609" diaginertia="3.2e-05 1.8e-05 1.8e-05"/>
                <joint name="ankle_pitch_l_joint" pos="0 0 0" axis="0 1 0" range="-1.22 0.5236" damping="2.5"/>
                <geom type="mesh" contype="0" conaffinity="0" group="1" density="0" rgba="0.752941 0.752941 0.752941 1" mesh="ankle_pitch_l_link"/>
                <body name="ankle_roll_l_link">
                  <inertial pos="0.021235 0 -0.032883" quat="0 0.747289 0 0.6645" mass="1.01738" diaginertia="0.0063132 0.006055 0.000954799"/>
                  <joint name="ankle_roll_l_joint" pos="0 0 0" axis="1 0 0" range="-0.4363 0.4363" damping="1.4"/>
                  <geom type="mesh" contype="0" conaffinity="0" group="1" density="0" rgba="0.752941 0.752941 0.752941 1" mesh="ankle_roll_l_link"/>
                </body>
              </body>
            </body>
          </body>
        </body>
      </body>
      <body name="hip_roll_r_link" pos="0 -0.028 -0.0857">
        <inertial pos="-0.001848 -0.055849 -0.036017" quat="-0.242041 0.661501 -0.270146 0.656394" mass="0.672983" diaginertia="0.0035288 0.00296741 0.00101678"/>
        <joint name="hip_roll_r_joint" pos="0 0 0" axis="1 0 0" range="-0.79 0.79" damping="10"/>
        <geom type="mesh" contype="0" conaffinity="0" group="1" density="0" rgba="0.752941 0.752941 0.752941 1" mesh="hip_roll_r_link"/>
        <body name="hip_pitch_r_link" pos="0 -0.122 -0.046">
          <inertial pos="0.001081 8.8e-05 -0.013133" quat="0.706193 -0.0604083 -0.0464278 0.703908" mass="3.95191" diaginertia="0.0155995 0.0108766 0.00930186"/>
          <joint name="hip_pitch_r_joint" pos="0 0 0" axis="0 1 0" range="-2.79 2.09" damping="10"/>
          <geom type="mesh" contype="0" conaffinity="0" group="1" density="0" rgba="0.752941 0.752941 0.752941 1" mesh="hip_pitch_r_link"/>
          <body name="hip_yaw_r_link" pos="0 0 -0.0987">
            <inertial pos="0.004102 0.006542 -0.121068" quat="0.727633 0.0149542 -0.0129439 0.685682" mass="6.6708" diaginertia="0.0533758 0.0495596 0.0178685"/>
            <joint name="hip_yaw_r_joint" pos="0 0 0" axis="0 0 1" range="-1.04 1.04" damping="5"/>
            <geom type="mesh" contype="0" conaffinity="0" group="1" density="0" rgba="0.752941 0.752941 0.752941 1" mesh="hip_yaw_r_link"/>
            <geom size="0.03 0.1" pos="0 0 -0.1" type="cylinder" rgba="0.752941 0.752941 0.752941 1"/>
            <body name="knee_pitch_r_link" pos="0 0.00035002 -0.3013">
              <inertial pos="0.00018 -0.001915 -0.178653" quat="0.669257 0.0403837 0.0200239 0.741662" mass="2.31269" diaginertia="0.0309319 0.0304477 0.00269639"/>
              <joint name="knee_pitch_r_joint" pos="0 0 0" axis="0 1 0" range="0 2.39" damping="10"/>
              <geom type="mesh" contype="0" conaffinity="0" group="1" density="0" rgba="0.752941 0.752941 0.752941 1" mesh="knee_pitch_r_link"/>
              <geom size="0.03 0.15" pos="0 0 -0.15" type="cylinder" rgba="0.752941 0.752941 0.752941 1"/>
              <body name="ankle_pitch_r_link" pos="0 0.00074981 -0.4">
                <inertial pos="0 0 0" quat="0.5 0.5 -0.5 0.5" mass="0.111609" diaginertia="3.2e-05 1.8e-05 1.8e-05"/>
                <joint name="ankle_pitch_r_joint" pos="0 0 0" axis="0 1 0" range="-1.22 0.5236" damping="2.5"/>
                <geom type="mesh" contype="0" conaffinity="0" group="1" density="0" rgba="0.752941 0.752941 0.752941 1" mesh="ankle_pitch_r_link"/>
                <body name="ankle_roll_r_link">
                  <inertial pos="0.021235 0 -0.032883" quat="0 0.747289 0 0.6645" mass="1.01738" diaginertia="0.0063132 0.006055 0.000954799"/>
                  <joint name="ankle_roll_r_joint" pos="0 0 0" axis="1 0 0" range="-0.4363 0.4363" damping="1.4"/>
                  <geom type="mesh" contype="0" conaffinity="0" group="1" density="0" rgba="0.752941 0.752941 0.752941 1" mesh="ankle_roll_r_link"/>
                </body>
            </body>
          </body>
        </body>
      </body>
    </body>
    <body name="waist_yaw_link">
      <inertial pos="-0.000653583 -0.000898347 0.229466" quat="0.99954 -0.0226974 -0.00457088 -0.0195927" mass="22.6452" diaginertia="0.449334 0.391337 0.186475"/>
      <joint name="waist_yaw_joint" pos="0 0 0" axis="0 0 1" range="-2.96 3.14" actuatorfrcrange="-120 120" damping="10"/>
      <geom type="mesh" contype="0" conaffinity="0" group="1" density="0" rgba="0.752941 0.752941 0.752941 1" mesh="waist_yaw_link"/>
      <geom pos="0.06958 0 0.035588" quat="0.95882 0 0.284016 0" type="mesh" contype="0" conaffinity="0" group="1" density="0" rgba="0.752941 0.752941 0.752941 1" mesh="camera_body_front_link"/>
      <geom pos="-0.1054 0 0.29423" quat="0.216438 2.79111e-06 0.976296 2.79111e-06" type="mesh" contype="0" conaffinity="0" group="1" density="0" rgba="0.752941 0.752941 0.752941 1" mesh="camera_body_back_link"/>
      <body name="head_yaw_link" pos="-0.002 0 0.56508">
        <inertial pos="-0.000198116 0.000454283 0.00724628" quat="0.57671 0.539615 -0.401775 0.463463" mass="0.0883927" diaginertia="0.000107085 9.42377e-05 7.56772e-05"/>
        <joint name="head_yaw_joint" pos="0 0 0" axis="0 0 1" range="-1.57 1.57" actuatorfrcrange="-9 9" damping="10"/>
        <geom type="mesh" contype="0" conaffinity="0" group="1" density="0" rgba="0.752941 0.752941 0.752941 1" mesh="head_yaw_link"/>
        <body name="head_pitch_link" pos="0.01455 0 0.0304" quat="0.991445 0 0.130526 0">
          <inertial pos="-0.000274 0.004118 2.3e-05" quat="0.573495 0.563096 -0.428362 0.412957" mass="0.23046" diaginertia="9.53059e-05 9.17204e-05 5.39736e-05"/>
          <joint name="head_pitch_joint" pos="0 0 0" axis="0 1 0" range="-0.43 0.43" actuatorfrcrange="-9 9" damping="10"/>
          <geom type="mesh" contype="0" conaffinity="0" group="1" density="0" rgba="0.752941 0.752941 0.752941 1" mesh="head_pitch_link"/>
          <body name="head_roll_link">
            <inertial pos="0.0205566 -0.00602991 0.0551284" quat="0.161846 0.491723 0.170318 0.838455" mass="0.944627" diaginertia="0.00368656 0.00337287 0.00261384"/>
            <joint name="head_roll_joint" pos="0 0 0" axis="1 0 0" range="-0.43 0.43" actuatorfrcrange="-9 9" damping="10"/>
            <geom type="mesh" contype="0" conaffinity="0" group="1" density="0" rgba="0.752941 0.752941 0.752941 1" mesh="head_roll_link"/>
            <geom pos="0.052782 -6.5455e-05 0.067499" quat="0.991445 0 0.130526 0" type="mesh" contype="0" conaffinity="0" group="1" density="0" rgba="0.752941 0.752941 0.752941 1" mesh="camera_head_link"/>
          </body>
        </body>
      </body>
      <body name="shoulder_pitch_l_link" pos="0 0.14034 0.37677" quat="0.999048 0.0436192 0 0">
        <inertial pos="0.006486 0.068343 0.000219" quat="0.591341 0.393139 -0.57492 0.406478" mass="0.469057" diaginertia="0.000468095 0.000406799 0.000362107"/>
        <joint name="shoulder_pitch_l_joint" pos="0 0 0" axis="0 1 0" range="-2.96 2.96" damping="3"/>
        <geom type="mesh" contype="0" conaffinity="0" group="1" density="0" rgba="0.752941 0.752941 0.752941 1" mesh="shoulder_pitch_l_link"/>
        <body name="shoulder_roll_l_link" pos="0 0.073 0">
          <inertial pos="-0.000165 0.001557 -0.049098" quat="0.706276 -0.0203759 0.0112258 0.707554" mass="0.298029" diaginertia="0.00099885 0.000881052 0.000573098"/>
          <joint name="shoulder_roll_l_joint" pos="0 0 0" axis="1 0 0" range="-0.2618 3.4" damping="1.5"/>
          <geom type="mesh" contype="0" conaffinity="0" group="1" density="0" rgba="0.752941 0.752941 0.752941 1" mesh="shoulder_roll_l_link"/>
          <body name="shoulder_yaw_l_link" pos="0 0 -0.013">
            <inertial pos="0.00809 -0.00102 -0.082881" quat="0.996315 -0.0129283 -0.0731393 0.0428919" mass="0.93608" diaginertia="0.0041934 0.00415703 0.000708565"/>
            <joint name="shoulder_yaw_l_joint" pos="0 0 0" axis="0 0 1" range="-2.96 2.96" damping="1"/>
            <geom type="mesh" contype="0" conaffinity="0" group="1" density="0" rgba="0.752941 0.752941 0.752941 1" mesh="shoulder_yaw_l_link"/>
            <body name="elbow_pitch_l_link" pos="0.019998 0 -0.15">
              <inertial pos="-0.019072 3.1e-05 -0.195441" quat="0.999198 0.00319299 0.00605842 0.0394438" mass="0.553799" diaginertia="0.00848749 0.00844401 0.000474499"/>
              <joint name="elbow_pitch_l_joint" pos="0 0 0" axis="0 1 0" range="-2.61 0.261" damping="1"/>
              <geom type="mesh" contype="0" conaffinity="0" group="1" density="0" rgba="0.752941 0.752941 0.752941 1" mesh="elbow_pitch_l_link"/>
              <body name="elbow_yaw_l_link" pos="-0.02 0 -0.0543">
                <inertial pos="8e-05 0.00115 -0.069083" quat="0.999899 -0.012607 0.000668448 0.00659261" mass="0.990079" diaginertia="0.00296102 0.00287955 0.000420432"/>
                <joint name="elbow_yaw_l_joint" pos="0 0 0" axis="0 0 1" range="-2.9671 2.9671" damping="3"/>
                <geom type="mesh" contype="0" conaffinity="0" group="1" density="0" rgba="0.752941 0.752941 0.752941 1" mesh="elbow_yaw_l_link"/>
                <body name="wrist_pitch_l_link" pos="0 0.002 -0.1887">
                  <inertial pos="0.005341 0.000652 -0.018511" quat="0.314863 0.66524 0.28303 0.614988" mass="0.266415" diaginertia="0.000116841 0.000110463 7.36959e-05"/>
                  <joint name="wrist_pitch_l_joint" pos="0 0 0" axis="0 1 0" range="-1.3 1.65" damping="3"/>
                  <geom type="mesh" contype="0" conaffinity="0" group="1" density="0" rgba="0.752941 0.752941 0.752941 1" mesh="wrist_pitch_l_link"/>
                  <body name="wrist_roll_l_link" pos="5.0485e-05 0 -0.02">
                    <inertial pos="0.000194258 0.000435423 0.0269794" quat="0.998779 -0.0046566 -0.00299744 -0.0490834" mass="0.453244" diaginertia="0.000793041 0.000734548 0.000248766"/>
                    <joint name="wrist_roll_l_joint" pos="0 0 0" axis="1 0 0" range="-1.04 0.785" damping="3"/>
                    <geom type="mesh" contype="0" conaffinity="0" group="1" density="0" rgba="0.752941 0.752941 0.752941 1" mesh="wrist_roll_l_link"/>
                      <geom pos="-0.001 -0.001 -0.0347209" quat="1.89468e-08 0.707105 0.707108 1.89469e-08" type="mesh" contype="0" conaffinity="0" group="1" density="0" rgba="1 1 1 1" mesh="L_base_link"/>
                        <body name="left_thumb_1" pos="0.0194499 -0.0179601 -0.101071" quat="1.89468e-08 0.707105 -0.707108 -1.89469e-08">
                          <inertial pos="0.000853472 -0.00482216 -0.00482" quat="0.717045 0.65204 0.104666 0.223014" mass="0.00483" diaginertia="2.13881e-07 1.68735e-07 1.24674e-07"/>
                          <joint name="left_thumb_1_joint" pos="0 0 0" axis="0 0 1" range="0 1.24616" damping="3"/>
                          <geom type="mesh" contype="0" conaffinity="0" group="1" density="0" rgba="1 1 1 1" mesh="left_thumb_1"/>
                          <body name="left_thumb_2" pos="0.010735 -0.0090002 -0.0065" quat="0.429475 0.429477 0.56174 0.561738">
                            <inertial pos="-0.0194666 0.0163039 -0.00803847" quat="0.302305 0.639599 -0.30189 0.639051" mass="0.05759" diaginertia="1.70013e-05 1.42937e-05 5.29607e-06"/>
                            <joint name="left_thumb_2_joint" pos="0 0 0" axis="0 0 -1" range="0 0.48" damping="3"/>
                            <geom type="mesh" contype="0" conaffinity="0" group="1" density="0" rgba="1 1 1 1" mesh="left_thumb_2"/>
                            <body name="left_thumb_3" pos="-0.037617 0.041486 -0.0008">
                              <inertial pos="-0.00946662 0.00207562 -0.00719989" quat="0.455874 0.540645 -0.455723 0.540554" mass="0.00985" diaginertia="1.28966e-06 1.22915e-06 5.82719e-07"/>
                              <joint name="left_thumb_3_joint" pos="0 0 0" axis="0 0 -1" range="0 0.3578" damping="3"/>
                              <geom type="mesh" contype="0" conaffinity="0" group="1" density="0" rgba="1 1 1 1" mesh="left_thumb_3"/>
                              <body name="left_thumb_4" pos="-0.014957 0.017012 -0.0012">
                                <inertial pos="-0.00604904 0.00861521 -0.00600331" quat="0.437334 0.551597 -0.44343 0.554842" mass="0.00552" diaginertia="3.37472e-07 3.27117e-07 1.19552e-07"/>
                                <joint name="left_thumb_4_joint" pos="0 0 0" axis="0 0 -1" range="0 0.2775" damping="3"/>
                                <geom type="mesh" contype="0" conaffinity="0" group="1" density="0" rgba="1 1 1 1" mesh="left_thumb_4"/>
                              </body>
                            </body>
                          </body>
                        </body>
                        <body name="left_index_1" pos="0.019275 -0.000714744 -0.171671" quat="-0.508648 0.491197 -0.491199 0.50865">
                          <inertial pos="0.000852716 0.0119736 0.00599989" quat="0.474966 0.52733 -0.469884 0.524919" mass="0.01229" diaginertia="2.05873e-06 1.95619e-06 5.46223e-07"/>
                          <joint name="left_index_1_joint" pos="0 0 0" axis="0 0 -1" range="0 1.333" damping="3"/>
                          <geom type="mesh" contype="0" conaffinity="0" group="1" density="0" rgba="1 1 1 1" mesh="left_index_1"/>
                          <body name="left_index_2" pos="0.0080993 0.031095 0.001">
                            <inertial pos="0.00408345 0.0192602 0.00500003" quat="0.380746 0.596795 -0.379234 0.595861" mass="0.00633" diaginertia="1.14024e-06 1.12462e-06 1.08348e-07"/>
                            <joint name="left_index_2_joint" pos="0 0 0" axis="0 0 -1" range="0 1.527" damping="3"/>
                            <geom type="mesh" contype="0" conaffinity="0" group="1" density="0" rgba="1 1 1 1" mesh="left_index_2"/>
                          </body>
                        </body>
                        <body name="left_middle_1" pos="-5.00063e-05 -0.000714673 -0.171821" quat="-0.5 0.499998 -0.5 0.500002">
                          <inertial pos="0.000852878 0.0119736 0.00599989" quat="0.477083 0.528768 -0.467753 0.523453" mass="0.01229" diaginertia="2.05876e-06 1.9562e-06 5.46243e-07"/>
                          <joint name="left_middle_1_joint" pos="0 0 0" axis="0 0 -1" range="0 1.333" damping="3"/>
                          <geom type="mesh" contype="0" conaffinity="0" group="1" density="0" rgba="1 1 1 1" mesh="left_middle_1"/>
                          <body name="left_middle_2" pos="0.0080996 0.031095 0.001">
                            <inertial pos="0.00471132 0.0203464 0.00500014" quat="0.378343 0.597374 -0.378343 0.597374" mass="0.00681" diaginertia="1.43878e-06 1.42175e-06 1.17529e-07"/>
                            <joint name="left_middle_2_joint" pos="0 0 0" axis="0 0 -1" range="0 1.527" damping="3"/>
                            <geom type="mesh" contype="0" conaffinity="0" group="1" density="0" rgba="1 1 1 1" mesh="left_middle_2"/>
                          </body>
                        </body>
                        <body name="left_ring_1" pos="-0.019271 -0.000714603 -0.171001" quat="-0.48673 0.512925 -0.512927 0.486732">
                          <inertial pos="0.000852611 0.0119737 0.00599988" quat="0.475236 0.527557 -0.469622 0.524681" mass="0.01229" diaginertia="2.05874e-06 1.95619e-06 5.46218e-07"/>
                          <joint name="left_ring_1_joint" pos="0 0 0" axis="0 0 -1" range="0 1.333" damping="3"/>
                          <geom type="mesh" contype="0" conaffinity="0" group="1" density="0" rgba="1 1 1 1" mesh="left_ring_1"/>
                          <body name="left_ring_2" pos="0.0080989 0.031095 0.001">
                            <inertial pos="0.004083 0.0192603 0.005" quat="0.584289 0.675004 -0.136357 0.429398" mass="0.00633" diaginertia="7.9107e-07 7.9107e-07 7.9107e-07"/>
                            <joint name="left_ring_2_joint" pos="0 0 0" axis="0 0 -1" range="0 1.527" damping="3"/>
                            <geom type="mesh" contype="0" conaffinity="0" group="1" density="0" rgba="1 1 1 1" mesh="left_ring_2"/>
                            <geom type="mesh" rgba="1 1 1 1" mesh="left_ring_2"/>
                          </body>
                        </body>
                        <body name="left_little_1" pos="-0.038422 -0.000714533 -0.169181" quat="-0.473152 0.525476 -0.525478 0.473154">
                          <inertial pos="0.000851753 0.0119737 0.00599989" quat="0.474577 0.527033 -0.47032 0.525177" mass="0.01229" diaginertia="2.05873e-06 1.95619e-06 5.46221e-07"/>
                          <joint name="left_little_1_joint" pos="0 0 0" axis="0 0 -1" range="0 1.333" damping="3"/>
                          <geom type="mesh" contype="0" conaffinity="0" group="1" density="0" rgba="1 1 1 1" mesh="left_little_1"/>
                          <body name="left_little_2" pos="0.0080966 0.031096 0.001">
                            <inertial pos="0.00273891 0.0161633 0.00500586" quat="0.381249 0.595524 -0.381249 0.595524" mass="0.00525" diaginertia="6.6906e-07 6.5812e-07 8.59895e-08"/>
                            <joint name="left_little_2_joint" pos="0 0 0" axis="0 0 -1" range="0 1.527" damping="3"/>
                            <geom type="mesh" contype="0" conaffinity="0" group="1" density="0" rgba="1 1 1 1" mesh="left_little_2"/>
                            <geom type="mesh" rgba="1 1 1 1" mesh="left_little_2"/>
                          </body>
                        </body>
                  </body>
                </body>
              </body>
            </body>
          </body>
        </body>
      </body>
      <body name="shoulder_pitch_r_link" pos="0 -0.14034 0.37677" quat="0.999048 -0.0436192 0 0">
        <inertial pos="0.006486 -0.068343 0.000219" quat="0.393139 0.591341 -0.406478 0.57492" mass="0.469057" diaginertia="0.000468095 0.000406799 0.000362107"/>
        <joint name="shoulder_pitch_r_joint" pos="0 0 0" axis="0 1 0" range="-2.96 2.96" damping="3"/>
        <geom type="mesh" contype="0" conaffinity="0" group="1" density="0" rgba="0.752941 0.752941 0.752941 1" mesh="shoulder_pitch_r_link"/>
        <body name="shoulder_roll_r_link" pos="0 -0.073 0">
          <inertial pos="-0.000165 -0.001557 -0.049098" quat="0.707554 0.0112258 -0.0203759 0.706276" mass="0.298029" diaginertia="0.00099885 0.000881052 0.000573098"/>
          <joint name="shoulder_roll_r_joint" pos="0 0 0" axis="1 0 0" range="-3.4 0.2618" damping="1.5"/>
          <geom type="mesh" contype="0" conaffinity="0" group="1" density="0" rgba="0.752941 0.752941 0.752941 1" mesh="shoulder_roll_r_link"/>
          <geom type="mesh" rgba="0.752941 0.752941 0.752941 1" mesh="shoulder_roll_r_link"/>
          <body name="shoulder_yaw_r_link" pos="0 0 -0.013">
            <inertial pos="0.00809 0.00102 -0.082881" quat="0.996315 0.0129283 -0.0731393 -0.0428919" mass="0.93608" diaginertia="0.0041934 0.00415703 0.000708565"/>
            <joint name="shoulder_yaw_r_joint" pos="0 0 0" axis="0 0 1" range="-2.96 2.96" damping="1"/>
            <geom type="mesh" contype="0" conaffinity="0" group="1" density="0" rgba="0.752941 0.752941 0.752941 1" mesh="shoulder_yaw_r_link"/>
            <body name="elbow_pitch_r_link" pos="0.020003 0 -0.15">
              <inertial pos="-0.019072 -3.1e-05 -0.195441" quat="0.999198 -0.00319299 0.00605842 -0.0394438" mass="0.553799" diaginertia="0.00848749 0.00844401 0.000474499"/>
              <joint name="elbow_pitch_r_joint" pos="0 0 0" axis="0 1 0" range="-2.61 0.261" damping="1"/>
              <geom type="mesh" contype="0" conaffinity="0" group="1" density="0" rgba="0.752941 0.752941 0.752941 1" mesh="elbow_pitch_r_link"/>
              <geom type="mesh" rgba="0.752941 0.752941 0.752941 1" mesh="elbow_pitch_r_link"/>
              <body name="elbow_yaw_r_link" pos="-0.02 0 -0.0543">
                <inertial pos="8e-05 0.00115 -0.069083" quat="0.999899 -0.012607 0.000668448 0.00659261" mass="0.990079" diaginertia="0.00296102 0.00287955 0.000420432"/>
                <joint name="elbow_yaw_r_joint" pos="0 0 0" axis="0 0 1" range="-2.9671 2.9671" actuatorfrcrange="-15 15" damping="5"/>
                <geom type="mesh" contype="0" conaffinity="0" group="1" density="0" rgba="0.752941 0.752941 0.752941 1" mesh="elbow_yaw_r_link"/>
                <body name="wrist_pitch_r_link" pos="0 -0.002 -0.1887">
                  <inertial pos="0.005341 -0.000652 -0.018511" quat="0.614988 0.28303 0.66524 0.314863" mass="0.266415" diaginertia="0.000116841 0.000110463 7.36959e-05"/>
                  <joint name="wrist_pitch_r_joint" pos="0 0 0" axis="0 1 0" range="-1.3 1.65" actuatorfrcrange="-9 9" damping="5"/>
                  <geom type="mesh" contype="0" conaffinity="0" group="1" density="0" rgba="0.752941 0.752941 0.752941 1" mesh="wrist_pitch_r_link"/>
                  <body name="wrist_roll_r_link" pos="5.0485e-05 0 -0.02">
                    <inertial pos="0.00178763 -0.00227771 0.0240456" quat="0.998695 0.0112775 -0.00352924 0.0496938" mass="0.453244" diaginertia="0.000773418 0.000714599 0.000248756"/>
                    <joint name="wrist_roll_r_joint" pos="0 0 0" axis="1 0 0" range="-1.04 0.785" actuatorfrcrange="-9 9" damping="5"/>
                    <geom type="mesh" contype="0" conaffinity="0" group="1" density="0" rgba="0.752941 0.752941 0.752941 1" mesh="wrist_roll_r_link"/>
                        <geom pos="-0.001 -0.001 -0.0347209" quat="1.89468e-08 0.707105 0.707108 1.89469e-08" type="mesh" contype="0" conaffinity="0" group="1" density="0" rgba="1 1 1 1" mesh="R_base_link"/>
                        <body name="right_thumb_1" pos="0.0194499 0.0159601 -0.101071" quat="1.89468e-08 0.707105 0.707108 1.89469e-08">
                          <inertial pos="0.000853491 0.00482217 -0.00482" quat="0.62265 0.746734 -0.185656 -0.142219" mass="0.00483" diaginertia="2.12995e-07 1.70477e-07 1.23818e-07"/>
                          <joint name="right_thumb_1_joint" pos="0 0 0" axis="0 0 -1" range="0 1.24616" actuatorfrcrange="-50 50" damping="3"/>
                          <geom type="mesh" contype="0" conaffinity="0" group="1" density="0" rgba="1 1 1 1" mesh="right_thumb_1"/>
                          <body name="right_thumb_2" pos="0.0107353 0.00900018 -0.0065" quat="0.561736 0.561736 0.42948 0.42948">
                            <inertial pos="0.0194641 0.016298 -0.00803857" quat="0.638977 0.30145 -0.639673 0.302745" mass="0.05759" diaginertia="1.70013e-05 1.42937e-05 5.29607e-06"/>
                            <joint name="right_thumb_2_joint" pos="0 0 0" axis="0 0 1" range="0 0.48" actuatorfrcrange="-50 50" damping="3"/>
                            <geom type="mesh" contype="0" conaffinity="0" group="1" density="0" rgba="1 1 1 1" mesh="right_thumb_2"/>
                            <body name="right_thumb_3" pos="0.0376168 0.0414855 -0.0008">
                              <inertial pos="0.00946652 0.00207631 -0.00720001" quat="0.540569 0.455787 -0.540629 0.45581" mass="0.00985" diaginertia="1.28966e-06 1.22915e-06 5.82719e-07"/>
                              <joint name="right_thumb_3_joint" pos="0 0 0" axis="0 0 1" range="0 0.3578" actuatorfrcrange="-50 50" damping="3"/>
                              <geom type="mesh" contype="0" conaffinity="0" group="1" density="0" rgba="1 1 1 1" mesh="right_thumb_3"/>
                              <body name="right_thumb_4" pos="0.0149571 0.0170124 -0.0012">
                                <inertial pos="0.00604905 0.00861523 -0.00600329" quat="0.552019 0.437851 -0.554425 0.442915" mass="0.00552" diaginertia="3.37471e-07 3.27117e-07 1.19552e-07"/>
                                <joint name="right_thumb_4_joint" pos="0 0 0" axis="0 0 1" range="0 0.2775" actuatorfrcrange="-50 50" damping="3"/>
                                <geom type="mesh" contype="0" conaffinity="0" group="1" density="0" rgba="1 1 1 1" mesh="right_thumb_4"/>
                              </body>
                            </body>
                          </body>
                        </body>
                        <body name="right_index_1" pos="0.019275 -0.00128526 -0.171667" quat="-0.491197 0.508649 0.508651 -0.491199">
                          <inertial pos="0.000852715 0.0119736 -0.00599987" quat="0.525442 0.472889 -0.526818 0.471963" mass="0.01229" diaginertia="2.05873e-06 1.9562e-06 5.46223e-07"/>
                          <joint name="right_index_1_joint" pos="0 0 0" axis="0 -0.0697565 -0.997564" range="0 1.333" actuatorfrcrange="-50 50" damping="3"/>
                          <geom type="mesh" contype="0" conaffinity="0" group="1" density="0" rgba="1 1 1 1" mesh="right_index_1"/>
                          <body name="right_index_2" pos="0.00809927 0.0310949 -0.001">
                            <inertial pos="0.00408343 0.0192601 -0.005" quat="0.596349 0.380057 -0.596308 0.379923" mass="0.00633" diaginertia="1.14024e-06 1.12462e-06 1.08348e-07"/>
                            <joint name="right_index_2_joint" pos="0 0 0" axis="0 0 -1" range="0 1.527" actuatorfrcrange="-50 50" damping="3"/>
                            <geom type="mesh" contype="0" conaffinity="0" group="1" density="0" rgba="1 1 1 1" mesh="right_index_2"/>
                          </body>
                        </body>
                        <body name="right_middle_1" pos="0.00195001 -0.00128532 -0.171821" quat="-0.499999 0.499999 0.500001 -0.500001">
                          <inertial pos="0.000852856 0.0119736 -0.00399985" quat="0.524217 0.472069 -0.528046 0.472773" mass="0.01229" diaginertia="2.05874e-06 1.95622e-06 5.46242e-07"/>
                          <joint name="right_middle_1_joint" pos="0 0 0" axis="0 0 -1" range="0 1.333" actuatorfrcrange="-50 50" damping="3"/>
                          <geom type="mesh" contype="0" conaffinity="0" group="1" density="0" rgba="1 1 1 1" mesh="right_middle_1"/>
                          <body name="right_middle_2" pos="0.0080996 0.0310948 0.001">
                            <inertial pos="0.00471135 0.0203466 -0.00500003" quat="0.597374 0.378343 -0.597374 0.378343" mass="0.00681" diaginertia="1.43878e-06 1.42175e-06 1.17529e-07"/>
                            <joint name="right_middle_2_joint" pos="0 0 0" axis="0 0 -1" range="0 1.527" actuatorfrcrange="-50 50" damping="3"/>
                            <geom type="mesh" contype="0" conaffinity="0" group="1" density="0" rgba="1 1 1 1" mesh="right_middle_2"/>
                          </body>
                        </body>
                        <body name="right_ring_1" pos="-0.0192707 -0.0012854 -0.171003" quat="-0.512916 0.486739 0.486741 -0.512918">
                          <inertial pos="0.000852458 0.0119735 -0.00599989" quat="0.52521 0.472652 -0.527043 0.472207" mass="0.01229" diaginertia="2.05873e-06 1.95619e-06 5.46217e-07"/>
                          <joint name="right_ring_1_joint" pos="0 0 0" axis="0 0 -1" range="0 1.333" actuatorfrcrange="-50 50" damping="3"/>
                          <geom type="mesh" contype="0" conaffinity="0" group="1" density="0" rgba="1 1 1 1" mesh="right_ring_1"/>
                          <body name="right_ring_2" pos="0.00809886 0.031095 -0.001">
                            <inertial pos="0.00408287 0.01926 -0.00499998" quat="0.579084 0.405513 -0.61244 0.35375" mass="0.00633" diaginertia="1.14024e-06 1.12462e-06 1.0835e-07"/>
                            <joint name="right_ring_2_joint" pos="0 0 0" axis="0 0 -1" range="0 1.527" actuatorfrcrange="-50 50" damping="3"/>
                            <geom type="mesh" contype="0" conaffinity="0" group="1" density="0" rgba="1 1 1 1" mesh="right_ring_2"/>
                          </body>
                        </body>
                        <body name="right_little_1" pos="-0.0384223 -0.00128547 -0.169181" quat="-0.525482 0.473146 0.473148 -0.525484">
                          <inertial pos="0.000851611 0.0119735 -0.00599989" quat="0.525652 0.473057 -0.526567 0.471841" mass="0.01229" diaginertia="2.05873e-06 1.95619e-06 5.4622e-07"/>
                          <joint name="right_little_1_joint" pos="0 0 0" axis="0 0 -1" range="0 1.333" actuatorfrcrange="-50 50" damping="3"/>
                          <geom type="mesh" contype="0" conaffinity="0" group="1" density="0" rgba="1 1 1 1" mesh="right_little_1"/>
                          <body name="right_little_2" pos="0.0080966 0.031096 -0.001">
                            <inertial pos="0.0027393 0.01616 -0.00499668" quat="0.595524 0.381249 -0.595524 0.381249" mass="0.00525" diaginertia="6.6906e-07 6.5812e-07 8.59895e-08"/>
                            <joint name="right_little_2_joint" pos="0 0 0" axis="0 0 -1" range="0 1.527" actuatorfrcrange="-50 50" damping="3"/>
                            <geom type="mesh" contype="0" conaffinity="0" group="1" density="0" rgba="1 1 1 1" mesh="right_little_2"/>
                          </body>
                        </body>
                  </body>
                </body>
              </body>
            </body>
          </body>
        </body>
      </body>
    </body>
    </body>
  </worldbody>

  <actuator>
    <position name="hip_roll_l_joint" joint="hip_roll_l_joint" kp="700"/>
    <position name="hip_pitch_l_joint" joint="hip_pitch_l_joint" kp="700"/>
    <position name="hip_yaw_l_joint" joint="hip_yaw_l_joint" kp="500"/>
    <position name="knee_pitch_l_joint" joint="knee_pitch_l_joint" kp="700"/>
    <position name="ankle_pitch_l_joint" joint="ankle_pitch_l_joint" kp="30"/>
    <position name="ankle_roll_l_joint" joint="ankle_roll_l_joint" kp="16.8"/>

    <position name="hip_roll_r_joint" joint="hip_roll_r_joint" kp="700"/>
    <position name="hip_pitch_r_joint" joint="hip_pitch_r_joint" kp="700"/>
    <position name="hip_yaw_r_joint" joint="hip_yaw_r_joint" kp="500"/>
    <position name="knee_pitch_r_joint" joint="knee_pitch_r_joint" kp="700"/>
    <position name="ankle_pitch_r_joint" joint="ankle_pitch_r_joint" kp="30"/>
    <position name="ankle_roll_r_joint" joint="ankle_roll_r_joint" kp="16.8"/>

    <position name="waist_yaw_joint" joint="waist_yaw_joint" kp="700"/>
    <position name="head_yaw_joint" joint="head_yaw_joint" kp="700"/>
    <position name="head_pitch_joint" joint="head_pitch_joint" kp="700"/>
    <position name="head_roll_joint" joint="head_roll_joint" kp="700"/>

    <position name="shoulder_pitch_l_joint" joint="shoulder_pitch_l_joint" kp="60"/>
    <position name="shoulder_roll_l_joint" joint="shoulder_roll_l_joint" kp="20"/>
    <position name="shoulder_yaw_l_joint" joint="shoulder_yaw_l_joint" kp="10"/>
    <position name="elbow_pitch_l_joint" joint="elbow_pitch_l_joint" kp="10"/>
    <position name="elbow_yaw_l_joint" joint="elbow_yaw_l_joint" kp="10"/>
    <position name="wrist_pitch_l_joint" joint="elbow_yaw_l_joint" kp="10"/>
    <position name="wrist_roll_l_joint" joint="elbow_yaw_l_joint" kp="10"/>

    <position name="shoulder_pitch_r_joint" joint="shoulder_pitch_r_joint" kp="60"/>
    <position name="shoulder_roll_r_joint" joint="shoulder_roll_r_joint" kp="20"/>
    <position name="shoulder_yaw_r_joint" joint="shoulder_yaw_r_joint" kp="10"/>
    <position name="elbow_pitch_r_joint" joint="elbow_pitch_r_joint" kp="10"/>
    <position name="elbow_yaw_r_joint" joint="elbow_yaw_r_joint" kp="10"/>
    <position name="wrist_pitch_r_joint" joint="elbow_yaw_r_joint" kp="10"/>
    <position name="wrist_roll_r_joint" joint="elbow_yaw_r_joint" kp="10"/>

  </actuator>
  <sensor>
    <jointpos joint="hip_roll_l_joint" user="6"/>
    <jointpos joint="hip_pitch_l_joint" user="6"/>
    <jointpos joint="hip_yaw_l_joint" user="6"/>
    <jointpos joint="knee_pitch_l_joint" user="6"/>
    <jointpos joint="ankle_pitch_l_joint" user="6"/>
    <jointpos joint="ankle_roll_l_joint" user="6"/>
    <jointpos joint="hip_roll_r_joint" user="6"/>
    <jointpos joint="hip_pitch_r_joint" user="6"/>
    <jointpos joint="hip_yaw_r_joint" user="6"/>
    <jointpos joint="knee_pitch_r_joint" user="6"/>
    <jointpos joint="ankle_pitch_r_joint" user="6"/>
    <jointpos joint="ankle_roll_r_joint" user="6"/>

    <jointpos joint="waist_yaw_joint" user="6"/>
    <jointpos joint="head_yaw_joint" user="6"/>
    <jointpos joint="head_pitch_joint" user="6"/>
    <jointpos joint="head_roll_joint" user="6"/>

    <jointpos joint="shoulder_pitch_l_joint" user="6"/>
    <jointpos joint="shoulder_roll_l_joint" user="6"/>
    <jointpos joint="shoulder_yaw_l_joint" user="6"/>
    <jointpos joint="elbow_pitch_l_joint" user="6"/>
    <jointpos joint="elbow_yaw_l_joint" user="6"/>
    <jointpos joint="wrist_pitch_l_joint" user="6"/>
    <jointpos joint="wrist_roll_l_joint" user="6"/>
    <jointpos joint="shoulder_pitch_r_joint" user="6"/>
    <jointpos joint="shoulder_roll_r_joint" user="6"/>
    <jointpos joint="shoulder_yaw_r_joint" user="6"/>
    <jointpos joint="elbow_pitch_r_joint" user="6"/>
    <jointpos joint="elbow_yaw_r_joint" user="6"/>
    <jointpos joint="wrist_pitch_r_joint" user="6"/>
    <jointpos joint="wrist_roll_r_joint" user="6"/>

    <jointvel joint="hip_roll_l_joint" user="6"/>
    <jointvel joint="hip_pitch_l_joint" user="6"/>
    <jointvel joint="hip_yaw_l_joint" user="6"/>
    <jointvel joint="knee_pitch_l_joint" user="6"/>
    <jointvel joint="ankle_pitch_l_joint" user="6"/>
    <jointvel joint="ankle_roll_l_joint" user="6"/>
    <jointvel joint="hip_roll_r_joint" user="6"/>
    <jointvel joint="hip_pitch_r_joint" user="6"/>
    <jointvel joint="hip_yaw_r_joint" user="6"/>
    <jointvel joint="knee_pitch_r_joint" user="6"/>
    <jointvel joint="ankle_pitch_r_joint" user="6"/>
    <jointvel joint="ankle_roll_r_joint" user="6"/>

    <jointpos joint="waist_yaw_joint" user="6"/>
    <jointpos joint="head_yaw_joint" user="6"/>
    <jointpos joint="head_pitch_joint" user="6"/>
    <jointpos joint="head_roll_joint" user="6"/>

    <jointpos joint="shoulder_pitch_l_joint" user="6"/>
    <jointpos joint="shoulder_roll_l_joint" user="6"/>
    <jointpos joint="shoulder_yaw_l_joint" user="6"/>
    <jointpos joint="elbow_pitch_l_joint" user="6"/>
    <jointpos joint="elbow_yaw_l_joint" user="6"/>
    <jointpos joint="wrist_pitch_l_joint" user="6"/>
    <jointpos joint="wrist_roll_l_joint" user="6"/>
    <jointpos joint="shoulder_pitch_r_joint" user="6"/>
    <jointpos joint="shoulder_roll_r_joint" user="6"/>
    <jointpos joint="shoulder_yaw_r_joint" user="6"/>
    <jointpos joint="elbow_pitch_r_joint" user="6"/>
    <jointpos joint="elbow_yaw_r_joint" user="6"/>
    <jointpos joint="wrist_pitch_r_joint" user="6"/>
    <jointpos joint="wrist_roll_r_joint" user="6"/>

    <framequat name='orientation' objtype='site' noise='0.001' objname='imu'/>
    <framepos name='position' objtype='site' noise='0.001' objname='imu'/>
    <gyro name='angular-velocity' site='imu' noise='0.005' cutoff='34.9'/>
    <velocimeter name='linear-velocity' site='imu' noise='0.001' cutoff='30'/>
  </sensor>
</mujoco>
